Traceback (most recent call last):
  File "/usr/local/lib/python3.11/dist-packages/jupyter_cache/executors/utils.py", line 58, in single_nb_execution
    executenb(
  File "/usr/local/lib/python3.11/dist-packages/nbclient/client.py", line 1319, in execute
    return NotebookClient(nb=nb, resources=resources, km=km, **kwargs).execute()
           ^^^^^^^^^^^^^^^^^^^^^^^^^^^^^^^^^^^^^^^^^^^^^^^^^^^^^^^^^^^^^^^^^^^^^
  File "/usr/local/lib/python3.11/dist-packages/jupyter_core/utils/__init__.py", line 165, in wrapped
    return loop.run_until_complete(inner)
           ^^^^^^^^^^^^^^^^^^^^^^^^^^^^^^
  File "/usr/lib/python3.11/asyncio/base_events.py", line 654, in run_until_complete
    return future.result()
           ^^^^^^^^^^^^^^^
  File "/usr/local/lib/python3.11/dist-packages/nbclient/client.py", line 709, in async_execute
    await self.async_execute_cell(
  File "/usr/local/lib/python3.11/dist-packages/nbclient/client.py", line 1062, in async_execute_cell
    await self._check_raise_for_error(cell, cell_index, exec_reply)
  File "/usr/local/lib/python3.11/dist-packages/nbclient/client.py", line 918, in _check_raise_for_error
    raise CellExecutionError.from_cell_and_msg(cell, exec_reply_content)
nbclient.exceptions.CellExecutionError: An error occurred while executing the following cell:
------------------
Q1 = df_combined['euclidean_distance'].quantile(0.25)
Q3 = df_combined['euclidean_distance'].quantile(0.75)

IQR = Q3 - Q1

# Menentukan batas bawah dan atas
batas_bawah = Q1 - 1.5 * IQR
batas_atas = Q3 + 1.5 * IQR

# Ambil data outlier
outliers = df_combined[(df_combined['euclidean_distance'] < batas_bawah) |
                      (df_combined['euclidean_distance'] > batas_atas)]
outlier_terbesar = outliers.loc[outliers['euclidean_distance'].idxmax()]

print("Outlier Terbesar:")
print(tabulate(outlier_terbesar.to_frame().T, headers="keys", tablefmt="grid"))
------------------


[0;31m---------------------------------------------------------------------------[0m
[0;31mKeyError[0m                                  Traceback (most recent call last)
[0;32m/usr/local/lib/python3.11/dist-packages/pandas/core/indexes/base.py[0m in [0;36mget_loc[0;34m(self, key)[0m
[1;32m   3804[0m         [0;32mtry[0m[0;34m:[0m[0;34m[0m[0;34m[0m[0m
[0;32m-> 3805[0;31m             [0;32mreturn[0m [0mself[0m[0;34m.[0m[0m_engine[0m[0;34m.[0m[0mget_loc[0m[0;34m([0m[0mcasted_key[0m[0;34m)[0m[0;34m[0m[0;34m[0m[0m
[0m[1;32m   3806[0m         [0;32mexcept[0m [0mKeyError[0m [0;32mas[0m [0merr[0m[0;34m:[0m[0;34m[0m[0;34m[0m[0m

[0;32mindex.pyx[0m in [0;36mpandas._libs.index.IndexEngine.get_loc[0;34m()[0m

[0;32mindex.pyx[0m in [0;36mpandas._libs.index.IndexEngine.get_loc[0;34m()[0m

[0;32mpandas/_libs/hashtable_class_helper.pxi[0m in [0;36mpandas._libs.hashtable.PyObjectHashTable.get_item[0;34m()[0m

[0;32mpandas/_libs/hashtable_class_helper.pxi[0m in [0;36mpandas._libs.hashtable.PyObjectHashTable.get_item[0;34m()[0m

[0;31mKeyError[0m: 'euclidean_distance'

The above exception was the direct cause of the following exception:

[0;31mKeyError[0m                                  Traceback (most recent call last)
[0;32m<ipython-input-9-9c1872d44e4a>[0m in [0;36m<cell line: 0>[0;34m()[0m
[0;32m----> 1[0;31m [0mQ1[0m [0;34m=[0m [0mdf_combined[0m[0;34m[[0m[0;34m'euclidean_distance'[0m[0;34m][0m[0;34m.[0m[0mquantile[0m[0;34m([0m[0;36m0.25[0m[0;34m)[0m[0;34m[0m[0;34m[0m[0m
[0m[1;32m      2[0m [0mQ3[0m [0;34m=[0m [0mdf_combined[0m[0;34m[[0m[0;34m'euclidean_distance'[0m[0;34m][0m[0;34m.[0m[0mquantile[0m[0;34m([0m[0;36m0.75[0m[0;34m)[0m[0;34m[0m[0;34m[0m[0m
[1;32m      3[0m [0;34m[0m[0m
[1;32m      4[0m [0mIQR[0m [0;34m=[0m [0mQ3[0m [0;34m-[0m [0mQ1[0m[0;34m[0m[0;34m[0m[0m
[1;32m      5[0m [0;34m[0m[0m

[0;32m/usr/local/lib/python3.11/dist-packages/pandas/core/frame.py[0m in [0;36m__getitem__[0;34m(self, key)[0m
[1;32m   4100[0m             [0;32mif[0m [0mself[0m[0;34m.[0m[0mcolumns[0m[0;34m.[0m[0mnlevels[0m [0;34m>[0m [0;36m1[0m[0;34m:[0m[0;34m[0m[0;34m[0m[0m
[1;32m   4101[0m                 [0;32mreturn[0m [0mself[0m[0;34m.[0m[0m_getitem_multilevel[0m[0;34m([0m[0mkey[0m[0;34m)[0m[0;34m[0m[0;34m[0m[0m
[0;32m-> 4102[0;31m             [0mindexer[0m [0;34m=[0m [0mself[0m[0;34m.[0m[0mcolumns[0m[0;34m.[0m[0mget_loc[0m[0;34m([0m[0mkey[0m[0;34m)[0m[0;34m[0m[0;34m[0m[0m
[0m[1;32m   4103[0m             [0;32mif[0m [0mis_integer[0m[0;34m([0m[0mindexer[0m[0;34m)[0m[0;34m:[0m[0;34m[0m[0;34m[0m[0m
[1;32m   4104[0m                 [0mindexer[0m [0;34m=[0m [0;34m[[0m[0mindexer[0m[0;34m][0m[0;34m[0m[0;34m[0m[0m

[0;32m/usr/local/lib/python3.11/dist-packages/pandas/core/indexes/base.py[0m in [0;36mget_loc[0;34m(self, key)[0m
[1;32m   3810[0m             ):
[1;32m   3811[0m                 [0;32mraise[0m [0mInvalidIndexError[0m[0;34m([0m[0mkey[0m[0;34m)[0m[0;34m[0m[0;34m[0m[0m
[0;32m-> 3812[0;31m             [0;32mraise[0m [0mKeyError[0m[0;34m([0m[0mkey[0m[0;34m)[0m [0;32mfrom[0m [0merr[0m[0;34m[0m[0;34m[0m[0m
[0m[1;32m   3813[0m         [0;32mexcept[0m [0mTypeError[0m[0;34m:[0m[0;34m[0m[0;34m[0m[0m
[1;32m   3814[0m             [0;31m# If we have a listlike key, _check_indexing_error will raise[0m[0;34m[0m[0;34m[0m[0m

[0;31mKeyError[0m: 'euclidean_distance'

